<?xml version="1.0" ?>
<robot name="irb2400_iiwa_cowork" xmlns:xacro="http://wiki.ros.org/xacro">
  <xacro:include filename="$(find tesseract_ros_examples)/urdf/lbr_iiwa_14_r820_macro.xacro" />
  <xacro:include filename="$(find tesseract_support)/urdf/abb_irb2400.urdf" />

  <!-- This contains the macro "ses_part_macro" that places the clip wrt the tool tip -->
  <xacro:include filename="$(find tesseract_ros_examples)/urdf/puzzle_mount.xacro" />
  <xacro:include filename="$(find tesseract_ros_examples)/urdf/grinder.xacro" />

  <link name="world"/>

  <link name="table">
    <visual>
      <geometry>
        <box size="6.0 2.0 0.05"/>
      </geometry>
    </visual>
    <collision>
      <geometry>
        <box size="1.0 1.0 0.05"/>
      </geometry>
    </collision>
  </link>

  <link name="iiwa_mount">
    <visual>
      <geometry>
        <box size="0.3 0.3 0.3"/>
      </geometry>
    </visual>
    <collision>
      <geometry>
        <box size="0.3 0.3 0.3"/>
      </geometry>
    </collision>
  </link>

  <xacro:kuka_lbr_iiwa_14_r820 prefix="iiwa_"/>
  <xacro:grinder prefix=""/>
  <xacro:puzzle_piece prefix=""/>

  <joint name="world_to_abb" type="fixed">
    <parent link="table"/>
    <child link="base_link"/>
    <origin xyz="-1.0 0 0" rpy="0 0 0"/>
  </joint>

  <joint name="world_to_table" type="fixed">
    <parent link="world"/>
    <child link="table"/>
    <origin xyz="0 0 0" rpy="0 0 0"/>
  </joint>

  <link name="link_grinder"/>
  <joint name="table_to_grinder" type="fixed">
    <parent link="table"/>
    <child link="link_grinder"/>
    <origin xyz="0.35 -0.35 0.125" rpy="0 0 0"/>
  </joint>

  <link name="link_grinder_1"/>
  <joint name="joint_aux1" type="revolute">
    <parent link="link_grinder"/>
    <child link="link_grinder_1"/>
    <origin xyz="0 0 0" rpy="0 0 0"/>
    <axis xyz="0 0 1" />
    <limit lower="-3.14159" upper="3.14159" effort="0" velocity="1.0" />
  </joint>

  <joint name="joint_aux2" type="revolute">
    <parent link="link_grinder_1"/>
    <child link="grinder_base"/>
    <origin xyz="0 0 0" rpy="0 0 0"/>
    <axis xyz="0 1 0" />
    <limit lower="-0.785398" upper="0.785398" effort="0" velocity="1.0" />
  </joint>

  <joint name="to_iiwa_mount" type="fixed">
    <parent link="table"/>
    <child link="iiwa_mount"/>
    <origin xyz="0.75 0 0.175" rpy="0 0 0"/>
  </joint>

  <joint name="iiwa_mount_to_iiwa_baselink" type="fixed">
    <parent link="iiwa_mount"/>
    <child link="iiwa_base_link"/>
    <origin xyz="0 0 0.15" rpy="0 0 0"/>
  </joint>

  <joint name="robot_tool" type="fixed">
    <parent link="iiwa_tool0"/>
    <child link="ee_mount"/>
    <origin xyz="0 0 0" rpy="1.5708 0 0"/>
  </joint>

</robot>
