<?xml version="1.0" ?>
<!-- =================================================================================== -->
<!-- |    This document was autogenerated by xacro from car_seat_demo.xacro            | -->
<!-- |    EDITING THIS FILE BY HAND IS NOT RECOMMENDED                                 | -->
<!-- =================================================================================== -->
<robot name="car_seat_demo">
  <!-- link list -->
  <link name="base_link">
    <visual>
      <geometry>
        <mesh filename="package://tesseract_support/meshes/sia20d/visual/MOTOMAN_BASE.stl"/>
      </geometry>
      <material name="blue">
        <color rgba="0 0 1 1"/>
      </material>
    </visual>
    <collision>
      <geometry>
        <mesh filename="package://tesseract_support/meshes/sia20d/collision/MOTOMAN_BASE.stl"/>
      </geometry>
      <material name="yellow">
        <color rgba="0 1 1 1"/>
      </material>
    </collision>
  </link>
  <link name="link_s">
    <visual>
      <origin rpy="0 0 3.1416" xyz="0 0 0"/>
      <geometry>
        <mesh filename="package://tesseract_support/meshes/sia20d/visual/MOTOMAN_AXIS_S.stl"/>
      </geometry>
      <material name="silver">
        <color rgba="0.8 0.8 0.8 1"/>
      </material>
    </visual>
    <collision>
      <origin rpy="0 0 3.1416" xyz="0 0 0"/>
      <geometry>
        <mesh filename="package://tesseract_support/meshes/sia20d/collision/MOTOMAN_AXIS_S.stl"/>
      </geometry>
      <material name="yellow"/>
    </collision>
  </link>
  <link name="link_l">
    <visual>
      <origin rpy="1.57 3.1416 3.1416" xyz="0 0 0"/>
      <geometry>
        <mesh filename="package://tesseract_support/meshes/sia20d/visual/MOTOMAN_AXIS_L.stl"/>
      </geometry>
      <material name="blue"/>
    </visual>
    <collision>
      <origin rpy="1.57 3.1416 3.1416" xyz="0 0 0"/>
      <geometry>
        <mesh filename="package://tesseract_support/meshes/sia20d/collision/MOTOMAN_AXIS_L.stl"/>
      </geometry>
      <material name="yellow"/>
    </collision>
  </link>
  <link name="link_e">
    <visual>
      <origin rpy="0 0 0" xyz="0 0 0"/>
      <geometry>
        <mesh filename="package://tesseract_support/meshes/sia20d/visual/MOTOMAN_AXIS_E.stl"/>
      </geometry>
      <material name="silver"/>
    </visual>
    <collision>
      <origin rpy="0 0 0" xyz="0 0 0"/>
      <geometry>
        <mesh filename="package://tesseract_support/meshes/sia20d/collision/MOTOMAN_AXIS_E.stl"/>
      </geometry>
      <material name="yellow"/>
    </collision>
  </link>
  <link name="link_u">
    <visual>
      <origin rpy="1.57 -3.1415 3.1416" xyz="0 0 0"/>
      <geometry>
        <mesh filename="package://tesseract_support/meshes/sia20d/visual/MOTOMAN_AXIS_U.stl"/>
      </geometry>
      <material name="blue"/>
    </visual>
    <collision>
      <origin rpy="1.57 -3.1415 3.1416" xyz="0 0 0"/>
      <geometry>
        <mesh filename="package://tesseract_support/meshes/sia20d/collision/MOTOMAN_AXIS_U.stl"/>
      </geometry>
      <material name="yellow"/>
    </collision>
  </link>
  <link name="link_r">
    <visual>
      <origin rpy="0 0 0" xyz="0 0 0"/>
      <geometry>
        <mesh filename="package://tesseract_support/meshes/sia20d/visual/MOTOMAN_AXIS_R.stl"/>
      </geometry>
      <material name="silver"/>
    </visual>
    <collision>
      <origin rpy="0 0 0" xyz="0 0 0"/>
      <geometry>
        <mesh filename="package://tesseract_support/meshes/sia20d/collision/MOTOMAN_AXIS_R.stl"/>
      </geometry>
      <material name="yellow"/>
    </collision>
  </link>
  <link name="link_b">
    <visual>
      <origin rpy="-1.57 0 0" xyz="0 0 0"/>
      <geometry>
        <mesh filename="package://tesseract_support/meshes/sia20d/visual/MOTOMAN_AXIS_B.stl"/>
      </geometry>
      <material name="blue"/>
    </visual>
    <collision>
      <origin rpy="-1.57 0 0" xyz="0 0 0"/>
      <geometry>
        <mesh filename="package://tesseract_support/meshes/sia20d/collision/MOTOMAN_AXIS_B.stl"/>
      </geometry>
      <material name="yellow"/>
    </collision>
  </link>
  <link name="link_t">
    <visual>
      <geometry>
        <mesh filename="package://tesseract_support/meshes/sia20d/visual/MOTOMAN_AXIS_T.stl"/>
      </geometry>
      <material name="silver"/>
    </visual>
    <collision>
      <geometry>
        <mesh filename="package://tesseract_support/meshes/sia20d/collision/MOTOMAN_AXIS_T.stl"/>
      </geometry>
      <material name="yellow"/>
    </collision>
  </link>
  <link name="tool0"/>
  <!-- end of link list -->
  <!-- joint list -->
  <joint name="joint_s" type="revolute">
    <parent link="base_link"/>
    <child link="link_s"/>
    <origin rpy="0 0 0" xyz="0 0 0.41"/>
    <axis xyz="0 0 1"/>
    <limit effort="100" lower="-3.1416" upper="3.1416" velocity="2.26"/>
  </joint>
  <joint name="joint_l" type="revolute">
    <parent link="link_s"/>
    <child link="link_l"/>
    <origin rpy="0 0 0" xyz="0 0 0"/>
    <axis xyz="0 1 0"/>
    <limit effort="100" lower="-1.91" upper="1.91" velocity="2.26"/>
  </joint>
  <joint name="joint_e" type="revolute">
    <parent link="link_l"/>
    <child link="link_e"/>
    <origin rpy="0 0 0" xyz="0 0 0.49"/>
    <axis xyz="0 0 1"/>
    <limit effort="100" lower="-2.96" upper="2.96" velocity="2.96"/>
  </joint>
  <joint name="joint_u" type="revolute">
    <parent link="link_e"/>
    <child link="link_u"/>
    <origin rpy="0 0 0" xyz="0 0 0"/>
    <axis xyz="0 -1 0"/>
    <limit effort="100" lower="-2.26" upper="2.26" velocity="2.96"/>
  </joint>
  <joint name="joint_r" type="revolute">
    <parent link="link_u"/>
    <child link="link_r"/>
    <origin rpy="0 0 0" xyz="0 0 0.420"/>
    <axis xyz="0 0 -1"/>
    <limit effort="100" lower="-3.1416" upper="3.1416" velocity="3.48"/>
  </joint>
  <joint name="joint_b" type="revolute">
    <parent link="link_r"/>
    <child link="link_b"/>
    <origin rpy="0 0 0" xyz="0 0 0"/>
    <axis xyz="0 -1 0"/>
    <limit effort="100" lower="-1.91" upper="1.91" velocity="3.48"/>
  </joint>
  <joint name="joint_t" type="revolute">
    <parent link="link_b"/>
    <child link="link_t"/>
    <origin rpy="0 0 0" xyz="0 0 0.18"/>
    <axis xyz="0 0 -1"/>
    <limit effort="100" lower="-3.1416" upper="3.1416" velocity="6.97"/>
  </joint>
  <joint name="link_t-tool0" type="fixed">
    <origin rpy="0 0 -3.1416" xyz="0 0 0.0"/>
    <parent link="link_t"/>
    <child link="tool0"/>
  </joint>
  <!-- end of joint list -->
  <link name="world"/>
  <link name="car">
    <visual>
      <origin rpy="0 0 0" xyz="0 0 0"/>
      <geometry>
        <mesh filename="package://tesseract_support/meshes/car_seat/visual/car.stl"/>
      </geometry>
      <material name="gray">
        <color rgba="1.0 0.25 0.0 1"/>
      </material>
    </visual>
    <collision>
      <geometry>
        <mesh filename="package://tesseract_support/meshes/car_seat/collision/car_1.stl"/>
      </geometry>
    </collision>
    <collision>
      <geometry>
        <mesh filename="package://tesseract_support/meshes/car_seat/collision/car_2.stl"/>
      </geometry>
    </collision>
    <collision>
      <geometry>
        <mesh filename="package://tesseract_support/meshes/car_seat/collision/car_3.stl"/>
      </geometry>
    </collision>
    <collision>
      <geometry>
        <mesh filename="package://tesseract_support/meshes/car_seat/collision/car_4.stl"/>
      </geometry>
    </collision>
    <collision>
      <geometry>
        <mesh filename="package://tesseract_support/meshes/car_seat/collision/car_5.stl"/>
      </geometry>
    </collision>
    <collision>
      <geometry>
        <mesh filename="package://tesseract_support/meshes/car_seat/collision/car_6.stl"/>
      </geometry>
    </collision>
    <collision>
      <geometry>
        <mesh filename="package://tesseract_support/meshes/car_seat/collision/car_7.stl"/>
      </geometry>
    </collision>
    <collision>
      <geometry>
        <mesh filename="package://tesseract_support/meshes/car_seat/collision/car_8.stl"/>
      </geometry>
    </collision>
    <collision>
      <geometry>
        <mesh filename="package://tesseract_support/meshes/car_seat/collision/car_9.stl"/>
      </geometry>
    </collision>
    <collision>
      <geometry>
        <mesh filename="package://tesseract_support/meshes/car_seat/collision/car_10.stl"/>
      </geometry>
    </collision>
    <collision>
      <geometry>
        <mesh filename="package://tesseract_support/meshes/car_seat/collision/car_11.stl"/>
      </geometry>
    </collision>
    <collision>
      <geometry>
        <mesh filename="package://tesseract_support/meshes/car_seat/collision/car_12.stl"/>
      </geometry>
    </collision>
    <collision>
      <geometry>
        <mesh filename="package://tesseract_support/meshes/car_seat/collision/car_13.stl"/>
      </geometry>
    </collision>
    <collision>
      <geometry>
        <mesh filename="package://tesseract_support/meshes/car_seat/collision/car_14.stl"/>
      </geometry>
    </collision>
    <collision>
      <geometry>
        <mesh filename="package://tesseract_support/meshes/car_seat/collision/car_15.stl"/>
      </geometry>
    </collision>
    <collision>
      <geometry>
        <mesh filename="package://tesseract_support/meshes/car_seat/collision/car_16.stl"/>
      </geometry>
    </collision>
    <collision>
      <geometry>
        <mesh filename="package://tesseract_support/meshes/car_seat/collision/car_17.stl"/>
      </geometry>
    </collision>
    <collision>
      <geometry>
        <mesh filename="package://tesseract_support/meshes/car_seat/collision/car_18.stl"/>
      </geometry>
    </collision>
    <collision>
      <geometry>
        <mesh filename="package://tesseract_support/meshes/car_seat/collision/car_19.stl"/>
      </geometry>
    </collision>
    <collision>
      <geometry>
        <mesh filename="package://tesseract_support/meshes/car_seat/collision/car_20.stl"/>
      </geometry>
    </collision>
    <collision>
      <geometry>
        <mesh filename="package://tesseract_support/meshes/car_seat/collision/car_21.stl"/>
      </geometry>
    </collision>
    <collision>
      <geometry>
        <mesh filename="package://tesseract_support/meshes/car_seat/collision/car_22.stl"/>
      </geometry>
    </collision>
    <collision>
      <geometry>
        <mesh filename="package://tesseract_support/meshes/car_seat/collision/car_23.stl"/>
      </geometry>
    </collision>
    <collision>
      <geometry>
        <mesh filename="package://tesseract_support/meshes/car_seat/collision/car_24.stl"/>
      </geometry>
    </collision>
  </link>
  <link name="fence">
    <visual>
      <origin rpy="0 0 0" xyz="0 0 0"/>
      <geometry>
        <mesh filename="package://tesseract_support/meshes/car_seat/visual/fence_structure.dae"/>
      </geometry>
      <material name="gray"/>
    </visual>
    <visual>
      <origin rpy="0 0 0" xyz="0 0 0"/>
      <geometry>
        <mesh filename="package://tesseract_support/meshes/car_seat/visual/fence_mesh.dae"/>
      </geometry>
      <material name="gray"/>
    </visual>
    <collision>
      <origin rpy="0 0 0" xyz="-2.42 -2.250 0.86"/>
      <geometry>
        <box size="8.840 0.040 1.720"/>
      </geometry>
      <material name="yellow"/>
    </collision>
  </link>
  <link name="conveyor">
    <visual>
      <origin rpy="0 0 0" xyz="0 0 0"/>
      <geometry>
        <mesh filename="package://tesseract_support/meshes/car_seat/visual/conveyor.dae"/>
      </geometry>
      <material name="gray"/>
    </visual>
    <collision>
      <origin rpy="0 0 0" xyz="0 0 0.215"/>
      <geometry>
        <box size="2.995 1.320 0.430"/>
      </geometry>
      <material name="yellow"/>
    </collision>
  </link>
  <link name="rail">
    <visual>
      <origin rpy="0 0 0" xyz="0 0 0"/>
      <geometry>
        <mesh filename="package://tesseract_support/meshes/car_seat/visual/rail_structure.dae"/>
      </geometry>
      <material name="gray"/>
    </visual>
    <visual>
      <origin rpy="0 0 0" xyz="0 0 0"/>
      <geometry>
        <mesh filename="package://tesseract_support/meshes/car_seat/visual/rail_feet.dae"/>
      </geometry>
      <material name="gray"/>
    </visual>
    <collision>
      <origin rpy="0 0 0" xyz="-2.900 -1 0.125"/>
      <geometry>
        <box size="6.300 2.722 0.25"/>
      </geometry>
      <material name="yellow"/>
    </collision>
  </link>
  <link name="carriage">
    <visual>
      <origin rpy="0 0 0" xyz="0 0 0"/>
      <geometry>
        <mesh filename="package://tesseract_support/meshes/car_seat/visual/carriage_plate.stl"/>
      </geometry>
      <material name="gray"/>
    </visual>
    <collision>
      <origin rpy="0 0 0" xyz="-0.5 0 0.025"/>
      <geometry>
        <box size="1 0.722 0.050"/>
      </geometry>
      <material name="yellow"/>
    </collision>
  </link>
  <link name="end_effector">
    <visual>
      <origin rpy="0 0 0" xyz="0 0 0"/>
      <geometry>
        <mesh filename="package://tesseract_support/meshes/car_seat/visual/end_effector_simple.stl"/>
      </geometry>
      <material name="gray"/>
    </visual>
    <collision>
      <origin ryp="0 0 0" xyz="0 0 0"/>
      <geometry>
        <mesh filename="package://tesseract_support/meshes/car_seat/visual/end_effector_simple.stl"/>
      </geometry>
      <material name="yellow"/>
    </collision>
  </link>
  <!--<link name="${prefix}seat">
          <visual>
            <origin rpy="0 0 0" xyz="0 0 0"/>
            <geometry>
              <mesh scale="0.9 0.9 0.9" filename="package://tesseract_support/meshes/car_seat/visual/seat.dae"/>
            </geometry>
            <material name="gray"/>
          </visual>
          <collision>
            <origin ryp="0 0 0" xyz="0 0 0"/>
            <geometry>
              <mesh scale="0.9 0.9 0.9" filename="package://tesseract_support/meshes/car_seat/collision/seat_1.stl"/>
            </geometry>
            <material name="yellow"/>
          </collision>
          <collision>
            <origin ryp="0 0 0" xyz="0 0 0"/>
            <geometry>
              <mesh scale="0.9 0.9 0.9" filename="package://tesseract_support/meshes/car_seat/collision/seat_2.stl"/>
            </geometry>
            <material name="yellow"/>
          </collision>
          <collision>
            <origin ryp="0 0 0" xyz="0 0 0"/>
            <geometry>
              <mesh scale="0.9 0.9 0.9" filename="package://tesseract_support/meshes/car_seat/collision/seat_3.stl"/>
            </geometry>
            <material name="yellow"/>
          </collision>
          <collision>
            <origin ryp="0 0 0" xyz="0 0 0"/>
            <geometry>
              <mesh scale="0.9 0.9 0.9" filename="package://tesseract_support/meshes/car_seat/collision/seat_4.stl"/>
            </geometry>
            <material name="yellow"/>
          </collision>
          <collision>
            <origin ryp="0 0 0" xyz="0 0 0"/>
            <geometry>
              <mesh scale="0.9 0.9 0.9" filename="package://tesseract_support/meshes/car_seat/collision/seat_5.stl"/>
            </geometry>
            <material name="yellow"/>
          </collision>
          <collision>
            <origin ryp="0 0 0" xyz="0 0 0"/>
            <geometry>
              <mesh scale="0.9 0.9 0.9" filename="package://tesseract_support/meshes/car_seat/collision/seat_6.stl"/>
            </geometry>
            <material name="yellow"/>
          </collision>
          <collision>
            <origin ryp="0 0 0" xyz="0 0 0"/>
            <geometry>
              <mesh scale="0.9 0.9 0.9" filename="package://tesseract_support/meshes/car_seat/collision/seat_7.stl"/>
            </geometry>
            <material name="yellow"/>
          </collision>
          <collision>
            <origin ryp="0 0 0" xyz="0 0 0"/>
            <geometry>
              <mesh scale="0.9 0.9 0.9" filename="package://tesseract_support/meshes/car_seat/collision/seat_8.stl"/>
            </geometry>
            <material name="yellow"/>
          </collision>
          <collision>
            <origin ryp="0 0 0" xyz="0 0 0"/>
            <geometry>
              <mesh scale="0.9 0.9 0.9" filename="package://tesseract_support/meshes/car_seat/collision/seat_9.stl"/>
            </geometry>
            <material name="yellow"/>
          </collision>
          <collision>
            <origin ryp="0 0 0" xyz="0 0 0"/>
            <geometry>
              <mesh scale="0.9 0.9 0.9" filename="package://tesseract_support/meshes/car_seat/collision/seat_10.stl"/>
            </geometry>
            <material name="yellow"/>
          </collision>
        </link>-->
  <link name="cell_logo">
    <visual>
      <origin rpy="0 0 0" xyz="0 0 0"/>
      <geometry>
        <box size="3 0.01 1.3125"/>
      </geometry>
      <material name="white">
        <color rgba="1.0 1.0 1.0 1.0"/>
      </material>
    </visual>
    <visual>
      <origin rpy="1.570796 0 3.14159" xyz="-0.25 0.011 0.05"/>
      <geometry>
        <mesh filename="package://tesseract_support/meshes/car_seat/visual/ros_logo_solid.dae" scale="3 3 1.5"/>
      </geometry>
    </visual>
    <collision>
      <origin rpy="0 0 0" xyz="0 0 0"/>
      <geometry>
        <box size="3 0.011 1.3125"/>
      </geometry>
    </collision>
  </link>
  <joint name="car_world" type="fixed">
    <origin rpy="0 0 0" xyz="0 -0.2 0"/>
    <parent link="world"/>
    <child link="car"/>
  </joint>
  <joint name="fence_world" type="fixed">
    <origin rpy="0 0 0" xyz="2.5 0 0"/>
    <parent link="world"/>
    <child link="fence"/>
  </joint>
  <joint name="conveyor_world" type="fixed">
    <origin rpy="0 0 0" xyz="1.5 2.15 0"/>
    <parent link="world"/>
    <child link="conveyor"/>
  </joint>
  <joint name="rail_world" type="fixed">
    <origin rpy="0 0 0" xyz="3 1.2 0"/>
    <parent link="world"/>
    <child link="rail"/>
  </joint>
  <joint name="carriage_rail" type="prismatic">
    <origin rpy="0 0 0" xyz="0 0 0"/>
    <parent link="rail"/>
    <child link="carriage"/>
    <axis xyz="-1 0 0"/>
    <limit effort="0" lower="0" upper="5" velocity="0.5"/>
  </joint>
  <joint name="robot_carriage" type="fixed">
    <origin rpy="0 0 -1.570796" xyz="-0.2 0 0.25"/>
    <parent link="carriage"/>
    <child link="base_link"/>
  </joint>
  <joint name="robot_end_effector" type="fixed">
    <origin rpy="3.14159 -1.5707963 0" xyz="0 0 0"/>
    <parent link="tool0"/>
    <child link="end_effector"/>
  </joint>
  <!--        <joint name="${prefix}end_effector_seat" type="fixed">
          <origin rpy="0 0.29 1.57" xyz="0.14 -0.1 -0.46"/>
          <parent link="end_effector"/>
          <child link="seat"/>
        </joint>-->
  <joint name="logo_world" type="fixed">
    <origin rpy="0 0 0" xyz="2 -2.22 1.05"/>
    <parent link="world"/>
    <child link="cell_logo"/>
  </joint>
</robot>

