<?xml version="1.0" ?>
<!-- =================================================================================== -->
<!-- |    This document was autogenerated by xacro from online_planning_example.xacro  | -->
<!-- |    EDITING THIS FILE BY HAND IS NOT RECOMMENDED                                 | -->
<!-- =================================================================================== -->
<robot name="online_planning_example">
  <!-- Conversion were obtained from http://www.e-paint.co.uk/Lab_values.asp
       unless otherwise stated. -->
  <!-- Actual colors -->
  <!-- NCS 2070-Y60R orange, standard robot color 1974 - May 2014 -->
  <!-- RAL 7035 light grey (abb graphite white), standard robot color May 2014 - current -->
  <!-- RAL 9003 signal white (abb white), cleanroom robot color -->
  <!-- RAL 7032 pebble gray, controller -->
  <!-- RAL 7012 basalt gray (abb dark gray) , robot primer -->
  <!-- RAL 7021 black gray (abb black) , robot with dark link color -->
  <!-- Other robot colours availble, but not limited too. -->
  <!-- RAL 3001 signal red -->
  <!-- RAL 3002 carmine red -->
  <!-- RAL 5002 ultramarine blue -->
  <!-- RAL 5015 sky blue -->
  <!-- RAL 6002 leaf green -->
  <!-- RAL 9002 gray white -->
  <!-- RAL 9010 pure white -->
  <!-- approximations -->
  <!-- yellow, collision model -->
  <!-- link list -->
  <link name="base_link">
    <visual>
      <origin rpy="0 0 0" xyz="0 0 0"/>
      <geometry>
        <mesh filename="package://tesseract_support/meshes/abb_irb2400/irb2400/visual/base_link.dae"/>
      </geometry>
      <material name="">
        <color rgba="0.7372549 0.3490196 0.1607843 1"/>
      </material>
    </visual>
    <collision>
      <geometry>
        <mesh filename="package://tesseract_support/meshes/abb_irb2400/irb2400/collision/base_link.stl"/>
      </geometry>
      <material name="yellow">
        <color rgba="1 1 0 1"/>
      </material>
    </collision>
  </link>
  <link name="link_1">
    <visual>
      <origin rpy="0 0 0" xyz="0 0 0"/>
      <geometry>
        <mesh filename="package://tesseract_support/meshes/abb_irb2400/irb2400/visual/link_1.dae"/>
      </geometry>
      <material name="">
        <color rgba="0.7372549 0.3490196 0.1607843 1"/>
      </material>
    </visual>
    <collision>
      <origin rpy="0 0 0" xyz="0 0 0"/>
      <geometry>
        <mesh filename="package://tesseract_support/meshes/abb_irb2400/irb2400/collision/link_1.stl"/>
      </geometry>
    </collision>
  </link>
  <link name="link_2">
    <visual>
      <origin rpy="0 0 0" xyz="0 0 0"/>
      <geometry>
        <mesh filename="package://tesseract_support/meshes/abb_irb2400/irb2400/visual/link_2.dae"/>
      </geometry>
      <material name="">
        <color rgba="0.7372549 0.3490196 0.1607843 1"/>
      </material>
    </visual>
    <collision>
      <origin rpy="0 0 0" xyz="0 0 0"/>
      <geometry>
        <mesh filename="package://tesseract_support/meshes/abb_irb2400/irb2400/collision/link_2_whole.stl"/>
      </geometry>
    </collision>
  </link>
  <link name="link_3">
    <visual>
      <origin rpy="0 0 0" xyz="0 0 0"/>
      <geometry>
        <mesh filename="package://tesseract_support/meshes/abb_irb2400/irb2400/visual/link_3.dae"/>
      </geometry>
      <material name="">
        <color rgba="0.7372549 0.3490196 0.1607843 1"/>
      </material>
    </visual>
    <collision>
      <origin rpy="0 0 0" xyz="0 0 0"/>
      <geometry>
        <mesh filename="package://tesseract_support/meshes/abb_irb2400/irb2400/collision/link_3.stl"/>
      </geometry>
    </collision>
  </link>
  <link name="link_4">
    <visual>
      <origin rpy="0 0 0" xyz="0 0 0"/>
      <geometry>
        <mesh filename="package://tesseract_support/meshes/abb_irb2400/irb2400/visual/link_4.dae"/>
      </geometry>
      <material name="">
        <color rgba="0.7372549 0.3490196 0.1607843 1"/>
      </material>
    </visual>
    <collision>
      <origin rpy="0 0 0" xyz="0 0 0"/>
      <geometry>
        <mesh filename="package://tesseract_support/meshes/abb_irb2400/irb2400/collision/link_4.stl"/>
      </geometry>
    </collision>
  </link>
  <link name="link_5">
    <visual>
      <origin rpy="0 0 0" xyz="0 0 0"/>
      <geometry>
        <mesh filename="package://tesseract_support/meshes/abb_irb2400/irb2400/visual/link_5.dae"/>
      </geometry>
      <material name="">
        <color rgba="0.7372549 0.3490196 0.1607843 1"/>
      </material>
    </visual>
    <collision>
      <origin rpy="0 0 0" xyz="0 0 0"/>
      <geometry>
        <mesh filename="package://tesseract_support/meshes/abb_irb2400/irb2400/collision/link_5.stl"/>
      </geometry>
    </collision>
  </link>
  <link name="link_6">
    <visual>
      <origin rpy="0 0 0" xyz="0 0 0"/>
      <geometry>
        <mesh filename="package://tesseract_support/meshes/abb_irb2400/irb2400/visual/link_6.dae"/>
      </geometry>
      <material name="">
        <color rgba="0.1882353 0.1960784 0.2039216 1"/>
      </material>
    </visual>
    <collision>
      <origin rpy="0 0 0" xyz="0 0 0"/>
      <geometry>
        <mesh filename="package://tesseract_support/meshes/abb_irb2400/irb2400/collision/link_6.stl"/>
      </geometry>
    </collision>
  </link>
  <link name="tool0"/>
  <!-- end of link list -->
  <!-- joint list -->
  <joint name="joint_1" type="revolute">
    <origin rpy="0 0 0" xyz="0 0 0"/>
    <parent link="base_link"/>
    <child link="link_1"/>
    <axis xyz="0 0 1"/>
    <limit effort="0" lower="-3.1416" upper="3.1416" velocity="2.618"/>
  </joint>
  <joint name="joint_2" type="revolute">
    <origin rpy="0 0 0" xyz="0.1 0 0.615"/>
    <parent link="link_1"/>
    <child link="link_2"/>
    <axis xyz="0 1 0"/>
    <limit effort="0" lower="-1.7453" upper="1.9199" velocity="2.618"/>
  </joint>
  <joint name="joint_3" type="revolute">
    <origin rpy="0 0 0" xyz="0 0 0.705"/>
    <parent link="link_2"/>
    <child link="link_3"/>
    <axis xyz="0 1 0"/>
    <limit effort="0" lower="-1.0472" upper="1.1345" velocity="2.618"/>
  </joint>
  <joint name="joint_4" type="revolute">
    <origin rpy="0 0 0" xyz="0.258 0 0.135"/>
    <parent link="link_3"/>
    <child link="link_4"/>
    <axis xyz="1 0 0"/>
    <limit effort="0" lower="-3.49" upper="3.49" velocity="6.2832"/>
  </joint>
  <joint name="joint_5" type="revolute">
    <origin rpy="0 0 0" xyz="0.497 0 0"/>
    <parent link="link_4"/>
    <child link="link_5"/>
    <axis xyz="0 1 0"/>
    <limit effort="0" lower="-2.0944" upper="2.0944" velocity="6.2832"/>
  </joint>
  <joint name="joint_6" type="revolute">
    <origin rpy="0 0 0" xyz="0.085 0 0"/>
    <parent link="link_5"/>
    <child link="link_6"/>
    <axis xyz="1 0 0"/>
    <limit effort="0" lower="-6.9813" upper="6.9813" velocity="7.854"/>
  </joint>
  <joint name="joint_6-tool0" type="fixed">
    <parent link="link_6"/>
    <child link="tool0"/>
    <origin rpy="0 1.57079632679 0" xyz="0 0 0"/>
  </joint>
  <!-- end of joint list -->
  <!-- ROS base_link to ABB World Coordinates transform -->
  <link name="base"/>
  <joint name="base_link-base" type="fixed">
    <origin rpy="0 0 0" xyz="0 0 0"/>
    <parent link="base_link"/>
    <child link="base"/>
  </joint>
  <material name="tesseract_black">
    <color rgba="0.0 0.0 0.0 1.0"/>
  </material>
  <material name="tesseract_white">
    <color rgba="1.0 1.0 1.0 1.0"/>
  </material>
  <material name="tesseract_red">
    <color rgba="1.0 0.0 0.0 1.0"/>
  </material>
  <material name="tesseract_green">
    <color rgba="0.0 1.0 0.0 1.0"/>
  </material>
  <material name="tesseract_blue">
    <color rgba="0.0 0.0 1.0 1.0"/>
  </material>
  <material name="estop_red">
    <color rgba="0.8 0 0 0.05"/>
  </material>
  <link name="gantry_base">
    <!--      <visual>
        <origin xyz="0 0 0" rpy="0 0 0"/>
        <geometry>
          <mesh filename="package://tesseract_support/meshes/visual/base.ply"/>
        </geometry>
      </visual>-->
    <!-- Rails -->
    <visual>
      <origin rpy="0 0 0" xyz="3.5 6.0 2.5"/>
      <geometry>
        <box size="9.0 0.5 0.5"/>
      </geometry>
      <material name="tesseract_red"/>
    </visual>
    <visual>
      <origin rpy="0 0 0" xyz="3.5 0.0 2.5"/>
      <geometry>
        <box size="9.0 0.5 0.5"/>
      </geometry>
      <material name="tesseract_red"/>
    </visual>
    <!-- Columns -->
    <visual>
      <origin rpy="0 0 0" xyz="-0.5 0.0 1.25"/>
      <geometry>
        <box size="0.5 0.5 2.5"/>
      </geometry>
      <material name="tesseract_red"/>
    </visual>
    <visual>
      <origin rpy="0 0 0" xyz="3.1 0.0 1.25"/>
      <geometry>
        <box size="0.5 0.5 2.5"/>
      </geometry>
      <material name="tesseract_red"/>
    </visual>
    <visual>
      <origin rpy="0 0 0" xyz="6.7 0.0 1.25"/>
      <geometry>
        <box size="0.5 0.5 2.5"/>
      </geometry>
      <material name="tesseract_red"/>
    </visual>
    <visual>
      <origin rpy="0 0 0" xyz="-0.5 6.0 1.25"/>
      <geometry>
        <box size="0.5 0.5 2.5"/>
      </geometry>
      <material name="tesseract_red"/>
    </visual>
    <visual>
      <origin rpy="0 0 0" xyz="3.1 6.0 1.25"/>
      <geometry>
        <box size="0.5 0.5 2.5"/>
      </geometry>
      <material name="tesseract_red"/>
    </visual>
    <visual>
      <origin rpy="0 0 0" xyz="6.7 6.0 1.25"/>
      <geometry>
        <box size="0.5 0.5 2.5"/>
      </geometry>
      <material name="tesseract_red"/>
    </visual>
  </link>
  <link name="gantry_axis_1">
    <!--    <visual>
           <origin xyz="0 0 0" rpy="0 0 0"/>
           <geometry>
             <mesh filename="package://tesseract_support/meshes/visual/axis1.ply"/>
           </geometry>
         </visual>-->
    <visual>
      <origin rpy="0 0 0" xyz="0.0 3.0 0.1"/>
      <geometry>
        <box size="0.75 7.0 0.75"/>
      </geometry>
      <material name="tesseract_green"/>
    </visual>
  </link>
  <link name="gantry_axis_2">
    <!--    <visual>
        <origin xyz="0 0 0" rpy="0 0 0"/>
        <geometry>
          <mesh filename="package://tesseract_support/meshes/visual/axis2.ply"/>
        </geometry>
      </visual>-->
    <visual>
      <origin rpy="0 0 0" xyz="0.0 0.0 0.1"/>
      <geometry>
        <box size="1.0 1.0 1.0"/>
      </geometry>
      <material name="tesseract_blue"/>
    </visual>
  </link>
  <link name="gantry_flange"/>
  <joint name="gantry_axis_1" type="prismatic">
    <origin rpy="0 0 0" xyz="0.0 .0 2.4"/>
    <parent link="gantry_base"/>
    <child link="gantry_axis_1"/>
    <axis xyz="1 0 0"/>
    <limit effort="0" lower="0" upper="6.2" velocity="0.2"/>
  </joint>
  <joint name="gantry_axis_2" type="prismatic">
    <origin rpy="0 0 1.57" xyz="0 1.1 0"/>
    <parent link="gantry_axis_1"/>
    <child link="gantry_axis_2"/>
    <axis xyz="1 0 0"/>
    <limit effort="0" lower="0" upper="4.2" velocity="0.5"/>
  </joint>
  <joint name="gantry_flange" type="fixed">
    <origin rpy="3.14159 0 0" xyz="-0.18 -0.2 -.4"/>
    <parent link="gantry_axis_2"/>
    <child link="gantry_flange"/>
  </joint>
  <joint name="gantry_to_robot_base" type="fixed">
    <origin rpy="0 0 0" xyz="0 0 0"/>
    <parent link="gantry_flange"/>
    <child link="base_link"/>
  </joint>
  <link name="world"/>
  <joint name="world_to_gantry" type="fixed">
    <origin rpy="0 0 0" xyz="0 0 0"/>
    <parent link="world"/>
    <child link="gantry_base"/>
  </joint>
  <!-- Add a zone that should be kept free of humans -->
  <link name="robot_estop_zone">
    <visual>
      <origin rpy="0 0 0" xyz="0 0 1"/>
      <geometry>
        <cylinder length="2" radius="2.0"/>
      </geometry>
      <material name="estop_red"/>
    </visual>
    <collision>
      <origin rpy="0 0 0" xyz="0 0 1"/>
      <geometry>
        <cylinder length="2" radius="2.0"/>
      </geometry>
      <material name="estop_red"/>
    </collision>
  </link>
  <joint name="estop_zone" type="fixed">
    <origin rpy="0 0 0" xyz="0 0 0"/>
    <parent link="gantry_flange"/>
    <child link="robot_estop_zone"/>
  </joint>
  <link name="floor">
    <visual>
      <origin rpy="0 0 0" xyz="3.5 3.0 0.001"/>
      <geometry>
        <box size="9.0 8.0 0.001"/>
      </geometry>
      <material name="tesseract_white"/>
    </visual>
    <collision>
      <origin rpy="0 0 0" xyz="4.5 4.0 0.1"/>
      <geometry>
        <box size="9.0 8.0 0.001"/>
      </geometry>
    </collision>
  </link>
  <joint name="world_to_floor" type="fixed">
    <origin rpy="0 0 0" xyz="0 0 0"/>
    <parent link="world"/>
    <child link="floor"/>
  </joint>
  <!-- Add a "human" to the environment -->
  <link name="human_x"/>
  <link name="human_y"/>
  <link name="human_estop_zone">
    <visual>
      <origin rpy="0 0 0" xyz="0 0 1"/>
      <geometry>
        <cylinder length="2" radius="0.5"/>
      </geometry>
      <material name="estop_red"/>
    </visual>
    <collision>
      <origin rpy="0 0 0" xyz="0 0 0"/>
      <geometry>
        <cylinder length="2" radius="0.5"/>
      </geometry>
      <material name="estop_red"/>
    </collision>
  </link>
  <joint name="human_x_joint" type="prismatic">
    <origin rpy="0 0 0" xyz="3 0 0"/>
    <parent link="floor"/>
    <child link="human_x"/>
    <axis xyz="1 0 0"/>
    <limit effort="0" lower="-10.0" upper="10.0" velocity="0.5"/>
  </joint>
  <joint name="human_y_joint" type="prismatic">
    <origin rpy="0 0 0" xyz="0 4 0"/>
    <parent link="human_x"/>
    <child link="human_y"/>
    <axis xyz="0 1 0"/>
    <limit effort="0" lower="-10.0" upper="10.0" velocity="0.5"/>
  </joint>
  <joint name="human_estop_zone" type="fixed">
    <origin rpy="0 0 0" xyz="0 0 0"/>
    <parent link="human_y"/>
    <child link="human_estop_zone"/>
  </joint>
  <!-- Add target point TODO: See if this is even used -->
  <link name="target_x"/>
  <link name="target_y"/>
  <link name="target_z"/>
  <joint name="target_x_joint" type="prismatic">
    <origin rpy="0 0 0" xyz="5 0 0"/>
    <parent link="floor"/>
    <child link="target_x"/>
    <axis xyz="1 0 0"/>
    <limit effort="0" lower="-5.0" upper="1.0" velocity="0.5"/>
  </joint>
  <joint name="target_y_joint" type="prismatic">
    <origin rpy="0 0 0" xyz="0 3 0"/>
    <parent link="target_x"/>
    <child link="target_y"/>
    <axis xyz="0 1 0"/>
    <limit effort="0" lower="-3.0" upper="3.0" velocity="0.5"/>
  </joint>
  <joint name="target_z_joint" type="prismatic">
    <origin rpy="0 0 0" xyz="0 0 0.5"/>
    <parent link="target_y"/>
    <child link="target_z"/>
    <axis xyz="0 0 1"/>
    <limit effort="0" lower="-0.5" upper="0.5" velocity="0.5"/>
  </joint>
</robot>

