<?xml version="1.0" ?>
<!-- =================================================================================== -->
<!-- |    This document was autogenerated by xacro from pick_and_place_plan.xacro      | -->
<!-- |    EDITING THIS FILE BY HAND IS NOT RECOMMENDED                                 | -->
<!-- =================================================================================== -->
<robot name="robot">
  <!-- Create links -->
  <link name="world"/>
  <link name="base_link"/>
  <!-- link list -->
  <link name="iiwa_base_link">
    <visual>
      <origin rpy="0 0 0" xyz="0 0 0"/>
      <geometry>
        <mesh filename="package://tesseract_support/meshes/lbr_iiwa_14_r820/visual/base_link.dae"/>
      </geometry>
    </visual>
    <collision>
      <origin rpy="0 0 0" xyz="0 0 0"/>
      <geometry>
        <mesh filename="package://tesseract_support/meshes/lbr_iiwa_14_r820/collision/base_link.stl"/>
      </geometry>
    </collision>
  </link>
  <link name="iiwa_link_1">
    <visual>
      <origin rpy="0 0 0" xyz="0 0 0"/>
      <geometry>
        <mesh filename="package://tesseract_support/meshes/lbr_iiwa_14_r820/visual/link_1.dae"/>
      </geometry>
    </visual>
    <collision>
      <origin rpy="0 0 0" xyz="0 0 0"/>
      <geometry>
        <mesh filename="package://tesseract_support/meshes/lbr_iiwa_14_r820/collision/link_1.stl"/>
      </geometry>
    </collision>
  </link>
  <link name="iiwa_link_2">
    <visual>
      <origin rpy="0 0 0" xyz="0 0 0"/>
      <geometry>
        <mesh filename="package://tesseract_support/meshes/lbr_iiwa_14_r820/visual/link_2.dae"/>
      </geometry>
    </visual>
    <collision>
      <origin rpy="0 0 0" xyz="0 0 0"/>
      <geometry>
        <mesh filename="package://tesseract_support/meshes/lbr_iiwa_14_r820/collision/link_2.stl"/>
      </geometry>
    </collision>
  </link>
  <link name="iiwa_link_3">
    <visual>
      <origin rpy="0 0 0" xyz="0 0 0"/>
      <geometry>
        <mesh filename="package://tesseract_support/meshes/lbr_iiwa_14_r820/visual/link_3.dae"/>
      </geometry>
    </visual>
    <collision>
      <origin rpy="0 0 0" xyz="0 0 0"/>
      <geometry>
        <mesh filename="package://tesseract_support/meshes/lbr_iiwa_14_r820/collision/link_3.stl"/>
      </geometry>
    </collision>
  </link>
  <link name="iiwa_link_4">
    <visual>
      <origin rpy="0 0 0" xyz="0 0 0"/>
      <geometry>
        <mesh filename="package://tesseract_support/meshes/lbr_iiwa_14_r820/visual/link_4.dae"/>
      </geometry>
    </visual>
    <collision>
      <origin rpy="0 0 0" xyz="0 0 0"/>
      <geometry>
        <mesh filename="package://tesseract_support/meshes/lbr_iiwa_14_r820/collision/link_4.stl"/>
      </geometry>
    </collision>
  </link>
  <link name="iiwa_link_5">
    <visual>
      <origin rpy="0 0 0" xyz="0 0 0"/>
      <geometry>
        <mesh filename="package://tesseract_support/meshes/lbr_iiwa_14_r820/visual/link_5.dae"/>
      </geometry>
    </visual>
    <collision>
      <origin rpy="0 0 0" xyz="0 0 0"/>
      <geometry>
        <mesh filename="package://tesseract_support/meshes/lbr_iiwa_14_r820/collision/link_5.stl"/>
      </geometry>
    </collision>
  </link>
  <link name="iiwa_link_6">
    <visual>
      <origin rpy="0 0 0" xyz="0 0 0"/>
      <geometry>
        <mesh filename="package://tesseract_support/meshes/lbr_iiwa_14_r820/visual/link_6.dae"/>
      </geometry>
    </visual>
    <collision>
      <origin rpy="0 0 0" xyz="0 0 0"/>
      <geometry>
        <mesh filename="package://tesseract_support/meshes/lbr_iiwa_14_r820/collision/link_6.stl"/>
      </geometry>
    </collision>
  </link>
  <link name="iiwa_link_7">
    <visual>
      <origin rpy="0 0 0" xyz="0 0 0"/>
      <geometry>
        <mesh filename="package://tesseract_support/meshes/lbr_iiwa_14_r820/visual/link_7.dae"/>
      </geometry>
    </visual>
    <collision>
      <origin rpy="0 0 0" xyz="0 0 0"/>
      <geometry>
        <mesh filename="package://tesseract_support/meshes/lbr_iiwa_14_r820/collision/link_7.stl"/>
      </geometry>
    </collision>
  </link>
  <link name="iiwa_tool0"/>
  <!-- end of link list -->
  <!-- joint list -->
  <joint name="iiwa_joint_a1" type="revolute">
    <origin rpy="0 0 0" xyz="0 0 0"/>
    <parent link="iiwa_base_link"/>
    <child link="iiwa_link_1"/>
    <axis xyz="0 0 1"/>
    <limit effort="0" lower="-2.9668" upper="2.9668" velocity="1.4834"/>
  </joint>
  <joint name="iiwa_joint_a2" type="revolute">
    <origin rpy="0 0 0" xyz="-0.00043624 0 0.36"/>
    <parent link="iiwa_link_1"/>
    <child link="iiwa_link_2"/>
    <axis xyz="0 1 0"/>
    <limit effort="0" lower="-2.0942" upper="2.0942" velocity="1.4834"/>
  </joint>
  <joint name="iiwa_joint_a3" type="revolute">
    <origin rpy="0 0 0" xyz="0 0 0"/>
    <parent link="iiwa_link_2"/>
    <child link="iiwa_link_3"/>
    <axis xyz="0 0 1"/>
    <limit effort="0" lower="-2.9668" upper="2.9668" velocity="1.7452"/>
  </joint>
  <joint name="iiwa_joint_a4" type="revolute">
    <origin rpy="0 0 0" xyz="0.00043624 0 0.42"/>
    <parent link="iiwa_link_3"/>
    <child link="iiwa_link_4"/>
    <axis xyz="0 -1 0"/>
    <limit effort="0" lower="-2.0942" upper="2.0942" velocity="1.3089"/>
  </joint>
  <joint name="iiwa_joint_a5" type="revolute">
    <origin rpy="0 0 0" xyz="0 0 0"/>
    <parent link="iiwa_link_4"/>
    <child link="iiwa_link_5"/>
    <axis xyz="0 0 1"/>
    <limit effort="0" lower="-2.9668" upper="2.9668" velocity="2.2688"/>
  </joint>
  <joint name="iiwa_joint_a6" type="revolute">
    <origin rpy="0 0 0" xyz="0 0 0.4"/>
    <parent link="iiwa_link_5"/>
    <child link="iiwa_link_6"/>
    <axis xyz="0 1 0"/>
    <limit effort="0" lower="-2.0942" upper="2.0942" velocity="2.356"/>
  </joint>
  <joint name="iiwa_joint_a7" type="revolute">
    <origin rpy="0 0 0" xyz="0 0 0"/>
    <parent link="iiwa_link_6"/>
    <child link="iiwa_link_7"/>
    <axis xyz="0 0 1"/>
    <limit effort="0" lower="-3.0541" upper="3.0541" velocity="2.356"/>
  </joint>
  <joint name="iiwa_joint_a7-tool0" type="fixed">
    <origin rpy="0 0 0" xyz="0 0 0.126"/>
    <parent link="iiwa_link_7"/>
    <child link="iiwa_tool0"/>
    <axis xyz="0 0 0"/>
  </joint>
  <!-- end of joint list -->
  <!-- ROS base_link to KUKA $ROBROOT coordinate system transform -->
  <link name="iiwa_base"/>
  <joint name="iiwa_base_link-base" type="fixed">
    <origin rpy="0 0 0" xyz="0 0 0"/>
    <parent link="iiwa_base_link"/>
    <child link="iiwa_base"/>
  </joint>
  <material name="light_gray">
    <color rgba="0.7 0.7 0.7 1"/>
  </material>
  <material name="red">
    <color rgba="1.0 0.1 0.1 1"/>
  </material>
  <link name="workcell_base">
    <visual>
      <geometry>
        <mesh filename="package://tesseract_support/meshes/pick_and_place/workcell.STL"/>
      </geometry>
      <material name="light_gray"/>
    </visual>
    <collision name="workcell_table">
      <geometry>
        <box size="0.8 1.25 0.77153"/>
      </geometry>
      <origin xyz="0.0 0.3 -0.385765"/>
    </collision>
    <collision name="workcell_columnSW">
      <geometry>
        <box size="0.1 0.1 1.25"/>
      </geometry>
      <origin xyz="-.3302 -.2794 0.6"/>
    </collision>
    <collision name="workcell_columnsSE">
      <geometry>
        <box size="0.1 0.1 1.25"/>
      </geometry>
      <origin xyz=".3302 -.2794 0.6"/>
    </collision>
    <collision name="workcell_columnNW">
      <geometry>
        <box size="0.1 0.1 1.25"/>
      </geometry>
      <origin xyz="-.3302 0.8382 0.6"/>
      colors
    
    </collision>
    <collision name="workcell_columnNE">
      <geometry>
        <box size="0.1 0.1 1.25"/>
      </geometry>
      <origin xyz=".3302 0.8382 0.6"/>
    </collision>
    <collision name="workcell_top">
      <geometry>
        <box size="0.95 1.4 0.2"/>
      </geometry>
      <origin xyz="0.0 0.3 1.2"/>
    </collision>
  </link>
  <joint name="workcell_joint" type="fixed">
    <origin rpy="0 0 0" xyz="0.0 0.0 0.77153"/>
    <parent link="world"/>
    <child link="workcell_base"/>
  </joint>
  <link name="cabinet_1">
    <collision name="cabinet_1_back">
      <geometry>
        <box size="0.5969 0.0254 0.762"/>
      </geometry>
      <origin xyz=".2985 -.0127 -0.381"/>
    </collision>
    <collision name="cabinet_1_sideL">
      <geometry>
        <box size="0.0254 0.3048 0.762"/>
      </geometry>
      <origin xyz="0.0127 -0.1524 -0.381"/>
    </collision>
    <collision name="cabinet_1_sideR">
      <geometry>
        <box size="0.0254 0.3048 0.762"/>
      </geometry>
      <origin xyz="0.5969 -0.1524 -0.381"/>
    </collision>
    <collision name="cabinet_1_cabinet1">
      <geometry>
        <box size="0.5969 0.3048 0.0254"/>
      </geometry>
      <origin xyz=".2985 -0.1524  -0.7493"/>
    </collision>
    <collision name="cabinet_1_cabinet2">
      <geometry>
        <box size="0.5969 0.3048 0.0254"/>
      </geometry>
      <origin xyz=".2985 -0.1524  -0.508"/>
    </collision>
    <collision name="cabinet_1_cabinet3">
      <geometry>
        <box size="0.5969 0.3048 0.0254"/>
      </geometry>
      <origin xyz=".2985 -0.1524  -0.254"/>
    </collision>
    <collision name="cabinet_1_cabinet4">
      <geometry>
        <box size="0.5969 0.3048 0.0254"/>
      </geometry>
      <origin xyz=".2985 -0.1524  -0.0127"/>
    </collision>
  </link>
  <joint name="cabinet_1_joint" type="fixed">
    <origin rpy="0 0 0" xyz="-0.3048 1.016 0.771525"/>
    <parent link="workcell_base"/>
    <child link="cabinet_1"/>
  </joint>
  <!-- Create joints -->
  <joint name="workcell_base_to_base" type="fixed">
    <parent link="workcell_base"/>
    <child link="base_link"/>
    <origin rpy="0 0 1.5708" xyz="0 -0.0381 0.00953"/>
  </joint>
  <!-- Create joints -->
  <joint name="workcell_base_to_robot" type="fixed">
    <parent link="base_link"/>
    <child link="iiwa_base_link"/>
    <origin rpy="0 0 0" xyz="0.0 0 0.0"/>
  </joint>
</robot>

