<?xml version="1.0" ?>
<!-- =================================================================================== -->
<!-- |    This document was autogenerated by xacro from puzzle_piece_workcell.xacro    | -->
<!-- |    EDITING THIS FILE BY HAND IS NOT RECOMMENDED                                 | -->
<!-- =================================================================================== -->
<robot name="puzzle_piece_workcell">
  <link name="world"/>
  <link name="table">
    <visual>
      <geometry>
        <box size="1.0 1.0 0.05"/>
      </geometry>
    </visual>
    <collision>
      <geometry>
        <box size="1.0 1.0 0.05"/>
      </geometry>
    </collision>
  </link>
  <!-- link list -->
  <link name="base_link">
    <visual>
      <origin rpy="0 0 0" xyz="0 0 0"/>
      <geometry>
        <mesh filename="package://tesseract_support/meshes/lbr_iiwa_14_r820/visual/base_link.dae"/>
      </geometry>
    </visual>
    <collision>
      <origin rpy="0 0 0" xyz="0 0 0"/>
      <geometry>
        <mesh filename="package://tesseract_support/meshes/lbr_iiwa_14_r820/collision/base_link.stl"/>
      </geometry>
    </collision>
  </link>
  <link name="link_1">
    <visual>
      <origin rpy="0 0 0" xyz="0 0 0"/>
      <geometry>
        <mesh filename="package://tesseract_support/meshes/lbr_iiwa_14_r820/visual/link_1.dae"/>
      </geometry>
    </visual>
    <collision>
      <origin rpy="0 0 0" xyz="0 0 0"/>
      <geometry>
        <mesh filename="package://tesseract_support/meshes/lbr_iiwa_14_r820/collision/link_1.stl"/>
      </geometry>
    </collision>
  </link>
  <link name="link_2">
    <visual>
      <origin rpy="0 0 0" xyz="0 0 0"/>
      <geometry>
        <mesh filename="package://tesseract_support/meshes/lbr_iiwa_14_r820/visual/link_2.dae"/>
      </geometry>
    </visual>
    <collision>
      <origin rpy="0 0 0" xyz="0 0 0"/>
      <geometry>
        <mesh filename="package://tesseract_support/meshes/lbr_iiwa_14_r820/collision/link_2.stl"/>
      </geometry>
    </collision>
  </link>
  <link name="link_3">
    <visual>
      <origin rpy="0 0 0" xyz="0 0 0"/>
      <geometry>
        <mesh filename="package://tesseract_support/meshes/lbr_iiwa_14_r820/visual/link_3.dae"/>
      </geometry>
    </visual>
    <collision>
      <origin rpy="0 0 0" xyz="0 0 0"/>
      <geometry>
        <mesh filename="package://tesseract_support/meshes/lbr_iiwa_14_r820/collision/link_3.stl"/>
      </geometry>
    </collision>
  </link>
  <link name="link_4">
    <visual>
      <origin rpy="0 0 0" xyz="0 0 0"/>
      <geometry>
        <mesh filename="package://tesseract_support/meshes/lbr_iiwa_14_r820/visual/link_4.dae"/>
      </geometry>
    </visual>
    <collision>
      <origin rpy="0 0 0" xyz="0 0 0"/>
      <geometry>
        <mesh filename="package://tesseract_support/meshes/lbr_iiwa_14_r820/collision/link_4.stl"/>
      </geometry>
    </collision>
  </link>
  <link name="link_5">
    <visual>
      <origin rpy="0 0 0" xyz="0 0 0"/>
      <geometry>
        <mesh filename="package://tesseract_support/meshes/lbr_iiwa_14_r820/visual/link_5.dae"/>
      </geometry>
    </visual>
    <collision>
      <origin rpy="0 0 0" xyz="0 0 0"/>
      <geometry>
        <mesh filename="package://tesseract_support/meshes/lbr_iiwa_14_r820/collision/link_5.stl"/>
      </geometry>
    </collision>
  </link>
  <link name="link_6">
    <visual>
      <origin rpy="0 0 0" xyz="0 0 0"/>
      <geometry>
        <mesh filename="package://tesseract_support/meshes/lbr_iiwa_14_r820/visual/link_6.dae"/>
      </geometry>
    </visual>
    <collision>
      <origin rpy="0 0 0" xyz="0 0 0"/>
      <geometry>
        <mesh filename="package://tesseract_support/meshes/lbr_iiwa_14_r820/collision/link_6.stl"/>
      </geometry>
    </collision>
  </link>
  <link name="link_7">
    <visual>
      <origin rpy="0 0 0" xyz="0 0 0"/>
      <geometry>
        <mesh filename="package://tesseract_support/meshes/lbr_iiwa_14_r820/visual/link_7.dae"/>
      </geometry>
    </visual>
    <collision>
      <origin rpy="0 0 0" xyz="0 0 0"/>
      <geometry>
        <mesh filename="package://tesseract_support/meshes/lbr_iiwa_14_r820/collision/link_7.stl"/>
      </geometry>
    </collision>
  </link>
  <link name="tool0"/>
  <!-- end of link list -->
  <!-- joint list -->
  <joint name="joint_a1" type="revolute">
    <origin rpy="0 0 0" xyz="0 0 0"/>
    <parent link="base_link"/>
    <child link="link_1"/>
    <axis xyz="0 0 1"/>
    <limit effort="0" lower="-2.9668" upper="2.9668" velocity="1.4834"/>
  </joint>
  <joint name="joint_a2" type="revolute">
    <origin rpy="0 0 0" xyz="-0.00043624 0 0.36"/>
    <parent link="link_1"/>
    <child link="link_2"/>
    <axis xyz="0 1 0"/>
    <limit effort="0" lower="-2.0942" upper="2.0942" velocity="1.4834"/>
  </joint>
  <joint name="joint_a3" type="revolute">
    <origin rpy="0 0 0" xyz="0 0 0"/>
    <parent link="link_2"/>
    <child link="link_3"/>
    <axis xyz="0 0 1"/>
    <limit effort="0" lower="-2.9668" upper="2.9668" velocity="1.7452"/>
  </joint>
  <joint name="joint_a4" type="revolute">
    <origin rpy="0 0 0" xyz="0.00043624 0 0.42"/>
    <parent link="link_3"/>
    <child link="link_4"/>
    <axis xyz="0 -1 0"/>
    <limit effort="0" lower="-2.0942" upper="2.0942" velocity="1.3089"/>
  </joint>
  <joint name="joint_a5" type="revolute">
    <origin rpy="0 0 0" xyz="0 0 0"/>
    <parent link="link_4"/>
    <child link="link_5"/>
    <axis xyz="0 0 1"/>
    <limit effort="0" lower="-2.9668" upper="2.9668" velocity="2.2688"/>
  </joint>
  <joint name="joint_a6" type="revolute">
    <origin rpy="0 0 0" xyz="0 0 0.4"/>
    <parent link="link_5"/>
    <child link="link_6"/>
    <axis xyz="0 1 0"/>
    <limit effort="0" lower="-2.0942" upper="2.0942" velocity="2.356"/>
  </joint>
  <joint name="joint_a7" type="revolute">
    <origin rpy="0 0 0" xyz="0 0 0"/>
    <parent link="link_6"/>
    <child link="link_7"/>
    <axis xyz="0 0 1"/>
    <limit effort="0" lower="-3.0541" upper="3.0541" velocity="2.356"/>
  </joint>
  <joint name="joint_a7-tool0" type="fixed">
    <origin rpy="0 0 0" xyz="0 0 0.126"/>
    <parent link="link_7"/>
    <child link="tool0"/>
    <axis xyz="0 0 0"/>
  </joint>
  <!-- end of joint list -->
  <!-- ROS base_link to KUKA $ROBROOT coordinate system transform -->
  <link name="base"/>
  <joint name="base_link-base" type="fixed">
    <origin rpy="0 0 0" xyz="0 0 0"/>
    <parent link="base_link"/>
    <child link="base"/>
  </joint>
  <link name="grinder_base">
    <visual>
      <origin rpy="0 0 0" xyz="0 0 0"/>
      <geometry>
        <mesh filename="package://tesseract_support/meshes/puzzle_piece/grinder_visual.dae"/>
      </geometry>
    </visual>
    <collision>
      <origin rpy="0 0 0" xyz="0 0 0"/>
      <geometry>
        <mesh filename="package://tesseract_support/meshes/puzzle_piece/grinder_collision.dae"/>
      </geometry>
    </collision>
  </link>
  <link name="grinder_frame"/>
  <joint name="grinder_base_to_grinder_tip" type="fixed">
    <parent link="grinder_base"/>
    <child link="grinder_frame"/>
    <origin rpy="0 3.14159 0" xyz="0 0 0.1"/>
  </joint>
  <link name="ee_mount"/>
  <!-- link "ee_base" and connected joints-->
  <link name="ee_base">
    <visual>
      <geometry>
        <mesh filename="package://tesseract_support/meshes/puzzle_piece/puzzle_mount.stl"/>
      </geometry>
      &gt;
      
    </visual>
    <collision>
      <geometry>
        <mesh filename="package://tesseract_support/meshes/puzzle_piece/puzzle_mount.stl"/>
      </geometry>
    </collision>
  </link>
  <joint name="ee_mount-ee_base" type="fixed">
    <parent link="ee_mount"/>
    <child link="ee_base"/>
    <origin rpy="0 0 0" xyz="0 0 0"/>
  </joint>
  <!-- tool1 is the point that parts connect to the tool -->
  <link name="tool1"/>
  <joint name="ee_base-tool1" type="fixed">
    <parent link="ee_base"/>
    <child link="tool1"/>
    <origin rpy="0.523599 -0.523599 0" xyz="-0.0083 0.0541 0.0143"/>
  </joint>
  <link name="part">
    <visual>
      <geometry>
        <mesh filename="package://tesseract_support/meshes/puzzle_piece/puzzle_bent.dae"/>
      </geometry>
    </visual>
    <collision>
      <geometry>
        <mesh filename="package://tesseract_support/meshes/puzzle_piece/puzzle_bent.dae"/>
      </geometry>
    </collision>
  </link>
  <joint name="tool1-part" type="fixed">
    <parent link="tool1"/>
    <child link="part"/>
    <origin rpy="0 -0.2618 0" xyz="0.0110 0.0030 -0.0379"/>
  </joint>
  <joint name="world_to_table" type="fixed">
    <parent link="world"/>
    <child link="table"/>
    <origin rpy="0 0 0" xyz="0 0 0.5"/>
  </joint>
  <link name="link_grinder"/>
  <joint name="world_to_grinder" type="fixed">
    <parent link="world"/>
    <child link="link_grinder"/>
    <origin rpy="0 0 0" xyz="0.35 -0.35 0.6"/>
  </joint>
  <link name="link_grinder_1"/>
  <joint name="joint_aux1" type="revolute">
    <parent link="link_grinder"/>
    <child link="link_grinder_1"/>
    <origin rpy="0 0 0" xyz="0 0 0"/>
    <axis xyz="0 0 1"/>
    <limit effort="0" lower="-3.14159" upper="3.14159" velocity="1.0"/>
  </joint>
  <joint name="joint_aux2" type="revolute">
    <parent link="link_grinder_1"/>
    <child link="grinder_base"/>
    <origin rpy="0 0 0" xyz="0 0 0"/>
    <axis xyz="0 1 0"/>
    <limit effort="0" lower="-0.785398" upper="0.785398" velocity="1.0"/>
  </joint>
  <joint name="table_to_robot" type="fixed">
    <parent link="table"/>
    <child link="base_link"/>
    <origin rpy="0 0 0" xyz="0 0 0"/>
  </joint>
  <joint name="robot_tool" type="fixed">
    <parent link="tool0"/>
    <child link="ee_mount"/>
    <origin rpy="1.5708 0 0" xyz="0 0 0"/>
  </joint>
</robot>

